Workbook

Sheet Dashboard
A1: PROJECT 25 — CYBERSECURITY COMMAND CENTER
A4: PLAYER | B4: Zero | D4: STAT | E4: VALUE | F4: MEANING | H4: TRACK | I4: DONE | J4: TOTAL | K4: % | L4: PROGRESS
A5: CURRENT AGE | D5: Roadmap Months | E5: 62 | F5: Monthly missions | H5: Foundation | I5: =COUNTIFS(Roadmap!D2:D63,"Foundation",Roadmap!G2:G63,"Done") -> 0 | J5: =COUNTIF(Roadmap!D2:D63,"Foundation") -> 6 | K5: =IFERROR(I5/J5,0) -> 0 | L5: =REPT("█",ROUND(K5*20,0))&REPT("░",20-ROUND(K5*20,0)) -> ░░░░░░░░░░░░░░░░░░░░
A6: MISSION | B6: Blue + Red + Purple Team practitioner by 25 | D6: Months Done | E6: =COUNTIF(Roadmap!G2:G63,"Done") -> 0 | F6: Completed monthly missions | H6: Blue Team | I6: =COUNTIFS(Roadmap!D2:D63,"Blue Team",Roadmap!G2:G63,"Done") -> 0 | J6: =COUNTIF(Roadmap!D2:D63,"Blue Team") -> 18 | K6: =IFERROR(I6/J6,0) -> 0 | L6: =REPT("█",ROUND(K6*20,0))&REPT("░",20-ROUND(K6*20,0)) -> ░░░░░░░░░░░░░░░░░░░░
A7: CURRENT CERT | B7: CompTIA A+ | D7: Overall Progress | E7: =E6/E5 -> 0 | F7: % roadmap complete | H7: Red Team | I7: =COUNTIFS(Roadmap!D2:D63,"Red Team",Roadmap!G2:G63,"Done") -> 0 | J7: =COUNTIF(Roadmap!D2:D63,"Red Team") -> 16 | K7: =IFERROR(I7/J7,0) -> 0 | L7: =REPT("█",ROUND(K7*20,0))&REPT("░",20-ROUND(K7*20,0)) -> ░░░░░░░░░░░░░░░░░░░░
A8: NEXT CERT | B8: Network+ | D8: Total XP | E8: =SUM(Roadmap!H2:H63)+SUMIF(Projects!G2:G12,"Done",Projects!F2:F12) -> 0 | F8: Roadmap + project XP | H8: Purple Team | I8: =COUNTIFS(Roadmap!D2:D63,"Purple Team",Roadmap!G2:G63,"Done") -> 0 | J8: =COUNTIF(Roadmap!D2:D63,"Purple Team") -> 11 | K8: =IFERROR(I8/J8,0) -> 0 | L8: =REPT("█",ROUND(K8*20,0))&REPT("░",20-ROUND(K8*20,0)) -> ░░░░░░░░░░░░░░░░░░░░
A9: START | B9: September 2026 | D9: Level | E9: =INT(E8/500)+1 -> 1 | F9: Every 500 XP | H9: Engineering | I9: =COUNTIFS(Roadmap!D2:D63,"Engineering",Roadmap!G2:G63,"Done") -> 0 | J9: =COUNTIF(Roadmap!D2:D63,"Engineering") -> 3 | K9: =IFERROR(I9/J9,0) -> 0 | L9: =REPT("█",ROUND(K9*20,0))&REPT("░",20-ROUND(K9*20,0)) -> ░░░░░░░░░░░░░░░░░░░░
A10: TARGET | B10: October 2031 | D10: XP to Next Level | E10: =E9*500-E8 -> 500 | F10: Remaining to next level
H12: CERTIFICATION PIPELINE
A13: LEVEL SYSTEM | H13: A+ | I13: COMPLETED
A14: Level | B14: XP Band | C14: Title | D14: Unlock | E14: Reward | H14: Network+ | I14: NEXT
A15: 1 | B15: 0–499 | C15: IT Apprentice | D15: Start | E15: Build homelab | H15: Security+ | I15: UP NEXT
A16: 2 | B16: 500–999 | C16: Network Scout | D16: 500 XP | E16: Network+ | H16: CySA+ | I16: YEAR 2
A17: 3 | B17: 1,000–1,499 | C17: Security Rookie | D17: 1,000 XP | E17: Security+ | H17: SC-200 | I17: RECOMMENDED
A18: 4 | B18: 1,500–1,999 | C18: SOC Cadet | D18: 1,500 XP | E18: SIEM Lab | H18: OSCP+ | I18: MAJOR MILESTONE
A19: 5 | B19: 2,000–2,499 | C19: Threat Hunter | D19: 2,000 XP | E19: CySA+
A20: 6 | B20: 2,500–2,999 | C20: Junior Operator | D20: 2,500 XP | E20: SOC simulation
A21: 7 | B21: 3,000–3,499 | C21: Red Team Apprentice | D21: 3,000 XP | E21: AD lab
A22: 8 | B22: 3,500–3,999 | C22: Purple Operator | D22: 3,500 XP | E22: Purple exercise
A23: 9 | B23: 4,000–4,999 | C23: Security Engineer | D23: 4,000 XP | E23: Automation
A24: 10 | B24: 5,000+ | C24: Cybersecurity Practitioner | D24: 5,000 XP | E24: Final capstone
G25: MICROSOFT / RDP TRACK
G26: Metric | H26: Done | I26: Total | J26: Progress | K26: XP Earned | L26: XP Available
A27: HOW TO USE | G27: Microsoft Missions | H27: =COUNTIF('Microsoft Track'!K9:K60,"Done") -> 0 | I27: =COUNTA('Microsoft Track'!A9:A60) -> 42 | J27: =IFERROR(H27/I27,0) -> 0 | K27: =SUMIF('Microsoft Track'!K9:K60,"Done",'Microsoft Track'!J9:J60) -> 0 | L27: =SUM('Microsoft Track'!J9:J60) -> 4250
A28: Roadmap | B28: Set each month's Status to In Progress or Done. Done = 100 XP. | I28: Missions | J28: ='12-Month Starter'!A5 -> 46
A29: Projects | B29: When a project is genuinely complete, set Status to Done and add evidence links/notes. | G29: Microsoft Certification Priorities
A30: Weekly | B30: Every Sunday, set one measurable goal for the coming week. | G30: SC-900 | H30: Security / Identity Fundamentals | I30: 20 | J30: Target | K30: Entra + Defender + Sentinel | L30: HIGH
A31: Skill Matrix | B31: Move skills from Not Started → In Progress → Done as your practical ability improves. | G31: SC-300 | H31: Identity & Access Administrator | I31: 21–22 | J31: Target | K31: Entra / Conditional Access / PIM | L31: VERY HIGH
A32: Dashboard | B32: Use XP and progress as motivation—not as a substitute for real technical competence. | G32: AZ-104 | H32: Azure Administrator | I32: 21–22 | J32: Target | K32: Azure infrastructure | L32: VERY HIGH
G33: SC-200 | H33: Security Operations Analyst | I33: 21–22 | J33: Target | K33: Sentinel / Defender / KQL | L33: VERY HIGH
G34: MD-102 | H34: Endpoint Administrator | I34: 22–24 | J34: Optional | K34: Intune / AVD / Windows 365 | L34: HIGH
A36: NEW TRACKS ADDED
A38: Track | B38: Purpose | C38: Start | D38: Target | E38: Priority | F38: Status
A39: PowerShell & Bash | B39: Windows/Linux administration, automation, investigation | C39: Now | D39: 2026–2028 | E39: Very High | F39: Not Started
A40: Python Security | B40: Security tooling, APIs, parsing, SOC automation | C40: Now | D40: 2027–2031 | E40: Very High | F40: Not Started
A41: Git / GitHub | B41: Portfolio and professional development workflow | C41: Now | D41: 2026–2031 | E41: High | F41: In Progress
A42: Software Development | B42: C# / C++ / Java + software engineering | C42: Year 6+ | D42: 2031+ | E42: Future | F42: Planned
A44: BEYOND 25 — FUTURE SPECIALISATIONS
A45: Track | B45: Purpose | C45: Target | D45: Priority | E45: Status | F45: Next step
A46: Advanced Networking / CCNA | B46: Deep networking and troubleshooting | C46: 21–23 | D46: High | E46: Planned | F46: Network+ first; then CCNA when bandwidth allows
...

Sheet Roadmap
A1: Month | B1: Age | C1: Year | D1: Track | E1: Focus | F1: Monthly Mission | G1: Status | H1: XP | I1: Done? | J1: Notes
A2: 2026-09 | B2: 19 | C2: Year 1 | D2: Foundation | E2: Network+ / Linux / Git | F2: Network+ core; TCP/IP + subnetting; Linux CLI; Windows basics; GitHub setup; start homelab | G2: Not Started | H2: 0 | I2: No
A3: 2026-10 | B3: 20 | C3: Year 1 | D3: Foundation | E3: Networking + Ethical Hacking | F3: Subnetting; DNS/DHCP/VLAN/routing; methodology; Nmap; Bash automation; Wireshark traffic analysis | G3: Not Started | H3: 0 | I3: No
A4: 2026-11 | B4: 20 | C4: Year 1 | D4: Foundation | E4: Security + Windows Logs | F4: Security fundamentals; Wireshark; Metasploit concepts in lab; Windows Event Logs; PowerShell investigation | G4: Not Started | H4: 0 | I4: No
A5: 2026-12 | B5: 20 | C5: Year 1 | D5: Foundation | E5: Security+ + Python | F5: Security+ prep; Python log parser; Bash/Python automation; first professional technical write-up | G5: Not Started | H5: 0 | I5: No
A6: 2027-01 | B6: 20 | C6: Year 1 | D6: Foundation | E6: Security+ + Web | F6: Security+ exam window; HTTP/Burp; SQLi labs; Python port scanner in your own lab | G6: Not Started | H6: 0 | I6: No
A7: 2027-02 | B7: 20 | C7: Year 1 | D7: Networking + CCNA | E7: CCNA Core + Web | F7: CCNA routing/switching foundations; subnetting; VLANs; continue HTTP/Burp and safe web labs | G7: Not Started | H7: 0 | I7: No
A8: 2027-03 | B8: 20 | C8: Year 1 | D8: Networking + CCNA + Red/Blue | E8: CCNA + HTB + AD + SOC | F8: CCNA prep; HTB Pentester path; AD fundamentals; SOC alert triage; CV/LinkedIn security positioning | G8: Not Started | H8: 0 | I8: No
A9: 2027-04 | B9: 20 | C9: Year 1 | D9: Networking + Blue | E9: CCNA Exam + SIEM/KQL | F9: Target CCNA exam when practice scores show readiness; deploy small SIEM lab; Windows log ingestion; KQL fundamentals | G9: Not Started | H9: 0 | I9: No
A10: 2027-05 | B10: 20 | C10: Year 1 | D10: Blue + Web | E10: Incident Response + Web | F10: Phishing-to-compromise IR simulation; PortSwigger lab sprint; IOC enrichment; interview basics | G10: Not Started | H10: 0 | I10: No
A11: 2027-06 | B11: 20 | C11: Year 1 | D11: Red + Blue | E11: Lab Pentest + Detection | F11: Complete authorised lab pentest; write 5 detections; first attack→detect exercise; publish professional report | G11: Not Started | H11: 0 | I11: No
A12: 2027-07 | B12: 20 | C12: Year 1 | D12: Red + Blue | E12: AD + Threat Hunting | F12: Authorised AD lab assessment; BloodHound concepts; threat hunting; publish 2 technical write-ups | G12: Not Started | H12: 0 | I12: No
A13: 2027-08 | B13: 20 | C13: Year 1 | D13: Blue + Red | E13: DFIR + CTF + Review | F13: DFIR basics; beginner CTF; optional scoped bug-bounty practice; annual skills/portfolio review | G13: Not Started | H13: 0 | I13: No
A14: 2027-09 | B14: 20 | C14: Year 1 | D14: Foundation | E14: Year 1 Review | F14: Security assessment of own lab; professional report | G14: Not Started | H14: =IF(G14="Done",100,IF(G14="In Progress",50,0)) -> 0 | I14: =IF(G14="Done","Yes","No") -> No
A15: 2027-10 | B15: 21 | C15: Year 2 | D15: Blue Team | E15: SOC Foundations | F15: Windows/Linux logs; Event Viewer; syslog | G15: Not Started | H15: =IF(G15="Done",100,IF(G15="In Progress",50,0)) -> 0 | I15: =IF(G15="Done","Yes","No") -> No
A16: 2027-11 | B16: 21 | C16: Year 2 | D16: Blue Team | E16: SIEM | F16: Sentinel + Elastic fundamentals | G16: Not Started | H16: =IF(G16="Done",100,IF(G16="In Progress",50,0)) -> 0 | I16: =IF(G16="Done","Yes","No") -> No
A17: 2027-12 | B17: 21 | C17: Year 2 | D17: Blue Team | E17: KQL | F17: Queries; dashboards; alerting | G17: Not Started | H17: =IF(G17="Done",100,IF(G17="In Progress",50,0)) -> 0 | I17: =IF(G17="Done","Yes","No") -> No
A18: 2028-01 | B18: 21 | C18: Year 2 | D18: Blue Team | E18: MITRE ATT&CK | F18: Tactics/techniques; attack mapping | G18: Not Started | H18: =IF(G18="Done",100,IF(G18="In Progress",50,0)) -> 0 | I18: =IF(G18="Done","Yes","No") -> No
A19: 2028-02 | B19: 21 | C19: Year 2 | D19: Blue Team | E19: SOC | F19: Alert triage; phishing; suspicious logons | G19: Not Started | H19: =IF(G19="Done",100,IF(G19="In Progress",50,0)) -> 0 | I19: =IF(G19="Done","Yes","No") -> No
A20: 2028-03 | B20: 21 | C20: Year 2 | D20: Blue Team | E20: Threat Hunting | F20: Hunting hypotheses; queries | G20: Not Started | H20: =IF(G20="Done",100,IF(G20="In Progress",50,0)) -> 0 | I20: =IF(G20="Done","Yes","No") -> No
A21: 2028-04 | B21: 21 | C21: Year 2 | D21: Blue Team | E21: CySA+ | F21: Start CySA+; incident response | G21: Not Started | H21: =IF(G21="Done",100,IF(G21="In Progress",50,0)) -> 0 | I21: =IF(G21="Done","Yes","No") -> No
A22: 2028-05 | B22: 21 | C22: Year 2 | D22: Blue Team | E22: CySA+ | F22: Threat hunting; vulnerability management | G22: Not Started | H22: =IF(G22="Done",100,IF(G22="In Progress",50,0)) -> 0 | I22: =IF(G22="Done","Yes","No") -> No
A23: 2028-06 | B23: 21 | C23: Year 2 | D23: Blue Team | E23: CySA+ Exam | F23: Sit exam; post-exam lab sprint | G23: Not Started | H23: =IF(G23="Done",100,IF(G23="In Progress",50,0)) -> 0 | I23: =IF(G23="Done","Yes","No") -> No
A24: 2028-07 | B24: 21 | C24: Year 2 | D24: Blue Team | E24: IR | F24: Timeline building; Windows investigation | G24: Not Started | H24: =IF(G24="Done",100,IF(G24="In Progress",50,0)) -> 0 | I24: =IF(G24="Done","Yes","No") -> No
A25: 2028-08 | B25: 21 | C25: Year 2 | D25: Blue Team | E25: SOC Project | F25: Simulated phishing-to-lateral-movement incident | G25: Not Started | H25: =IF(G25="Done",100,IF(G25="In Progress",50,0)) -> 0 | I25: =IF(G25="Done","Yes","No") -> No
... A54: 2031-01 | B54: 24 | C54: Year 5 | D54: Blue Team | E54: DFIR | F54: Windows artifacts; timelines; persistence | G54: Not Started | H54: =IF(G54="Done",100,IF(G54="In Progress",50,0)) -> 0 | I54: =IF(G54="Done","Yes","No") -> No
A55: 2031-02 | B55: 24 | C55: Year 5 | D55: Blue Team | E55: DFIR + Malware Analysis | F55: Disk/memory concepts; Windows artifacts; malware triage; static/dynamic analysis fundamentals | G55: Not Started | H55: 0 | I55: No
A56: 2031-03 | B56: 24 | C56: Year 5 | D56: Blue Team | E56: Threat Hunting | F56: Advanced hunting; investigations | G56: Not Started | H56: =IF(G56="Done",100,IF(G56="In Progress",50,0)) -> 0 | I56: =IF(G56="Done","Yes","No") -> No
A57: 2031-04 | B57: 24 | C57: Year 5 | D57: Purple Team | E57: Purple Team | F57: Full attack chain; ATT&CK mapping | G57: Not Started | H57: =IF(G57="Done",100,IF(G57="In Progress",50,0)) -> 0 | I57: =IF(G57="Done","Yes","No") -> No
A58: 2031-05 | B58: 24 | C58: Year 5 | D58: Purple Team | E58: Detection Validation | F58: Control validation; measure gaps | G58: Not Started | H58: =IF(G58="Done",100,IF(G58="In Progress",50,0)) -> 0 | I58: =IF(G58="Done","Yes","No") -> No
A59: 2031-06 | B59: 24 | C59: Year 5 | D59: Purple Team | E59: Capstone | F59: Build final enterprise cyber range | G59: Not Started | H59: =IF(G59="Done",100,IF(G59="In Progress",50,0)) -> 0 | I59: =IF(G59="Done","Yes","No") -> No
A60: 2031-07 | B60: 24 | C60: Year 5 | D60: Purple Team | E60: Capstone | F60: Run full red/blue exercise | G60: Not Started | H60: =IF(G60="Done",100,IF(G60="In Progress",50,0)) -> 0 | I60: =IF(G60="Done","Yes","No") -> No
A61: 2031-08 | B61: 24 | C61: Year 5 | D61: Purple Team | E61: Capstone | F61: Incident + vulnerability + remediation reports | G61: Not Started | H61: =IF(G61="Done",100,IF(G61="In Progress",50,0)) -> 0 | I61: =IF(G61="Done","Yes","No") -> No
A62: 2031-09 | B62: 24 | C62: Year 5 | D62: Purple Team | E62: Capstone | F62: Executive report; portfolio polish; career review | G62: Not Started | H62: =IF(G62="Done",100,IF(G62="In Progress",50,0)) -> 0 | I62: =IF(G62="Done","Yes","No") -> No
A63: 2031-10 | B63: 25 | C63: Year 5 | D63: Capstone | E63: PROJECT 25 REVIEW | F63: Demonstrate attack, detect, investigate, remediate, automate | G63: Not Started | H63: =IF(G63="Done",100,IF(G63="In Progress",50,0)) -> 0 | I63: =IF(G63="Done","Yes","No") -> No

Sheet Skill Matrix
A1: Skill | B1: Track | C1: Target Age | D1: What Good Looks Like | E1: Status | F1: XP Value
A2: Networking | B2: Foundation | C2: 20 | D2: TCP/IP, subnetting, DNS, DHCP, VLANs, routing, VPNs | E2: Not Started | F2: 500
A3: Windows | B3: Foundation | C3: 20 | D3: Services, registry, Event Viewer, NTFS, PowerShell | E3: Not Started | F3: 500
A4: Linux | B4: Foundation | C4: 20 | D4: Bash, permissions, processes, SSH, logs | E4: Not Started | F4: 400
A5: Python | B5: Engineering | C5: 24 | D5: Automation, APIs, sockets, log parsing, security tooling | E5: Not Started | F5: 600
A6: PowerShell | B6: Engineering | C6: 24 | D6: Windows automation, investigation, administration | E6: Not Started | F6: 500
A7: Active Directory | B7: Red Team | C7: 23 | D7: LDAP, Kerberos, GPO, ACLs, AD CS, BloodHound | E7: Not Started | F7: 700
A8: SIEM | B8: Blue Team | C8: 22 | D8: Sentinel, Elastic, ingestion, queries, dashboards | E8: Not Started | F8: 600
A9: KQL | B9: Blue Team | C9: 22 | D9: Queries, hunting, detections | E9: Not Started | F9: 400
A10: MITRE ATT&CK | B10: Blue Team | C10: 22 | D10: Map attacks to tactics/techniques | E10: Not Started | F10: 400
A11: Threat Hunting | B11: Blue Team | C11: 24 | D11: Hypothesis-driven hunting and investigation | E11: Not Started | F11: 600
A12: Incident Response | B12: Blue Team | C12: 24 | D12: Triage, timelines, containment, reporting | E12: Not Started | F12: 600
A13: Detection Engineering | B13: Purple Team | C13: 24 | D13: Engineering and validating detections | E13: Not Started | F13: 700
... A32: Malware Research & RE Automation | B32: Engineering | C32: 26+ | D32: Python/Ghidra scripting, triage automation, binary analysis workflows | E32: Planned | F32: 650

Sheet Certifications
A1: Certification | B1: Status | C1: Domain | D1: Target Age | E1: Target Window | F1: Priority
A2: CompTIA A+ | B2: Completed | C2: IT Foundations | D2: 19 | E2: Completed | F2: Done
A3: CompTIA Network+ | B3: Target | C3: Networking | D3: 20 | E3: Sep 2026–Jan 2027 | F3: Core
A4: CompTIA Security+ | B4: Target | C4: Security fundamentals | D4: 20 | E4: Jan–May 2027 | F4: Core
A5: Microsoft SC-900 | B5: Target | C5: Microsoft security / identity fundamentals | D5: 20 | E5: Late 2026 / early 2027 | F5: High
A6: Microsoft AZ-900 | B6: Optional | C6: Azure fundamentals | D6: 20–21 | E6: 2027; can be skipped if AZ-104 preparation covers the foundation | F6: Medium
A7: Cisco CCNA | B7: Target | C7: Networking / Security | D7: 20–21 | E7: Immediately after Security+; target mid/late 2027 | F7: Very High
A8: CompTIA CySA+ | B8: Target | C8: SOC / Blue Team | D8: 21 | E8: Year 2 | F8: Core
A9: Microsoft SC-300 | B9: Target | C9: Entra ID / Identity & Access | D9: 21–22 | E9: After AD + Entra fundamentals | F9: Very High
A10: Microsoft AZ-104 | B10: Target | C10: Azure administration | D10: 21–22 | E10: After Azure fundamentals + lab experience | F10: Very High
A11: Microsoft SC-200 | B11: Target | C11: Security Operations | D11: 21–22 | E11: After SIEM/KQL/SOC fundamentals | F11: Very High
A12: Microsoft MD-102 | B12: Optional | C12: Endpoint / Intune / Windows 365 | D12: 22–24 | E12: Strong fit for Windows/IT support background | F12: High
... A20: Malware Analysis / RE Certification | B20: Optional / Future | C20: DFIR / Reverse Engineering | D20: 25–27 | E20: Do not force a cert here; prioritise hands-on malware analysis first | F20: Optional
A22: CCNA SEQUENCE NOTE | B22: After Security+ | C22: Network+ gives the baseline; CCNA is the deeper networking milestone you want in 2027. Keep security practice running alongside it. | E22: Very High
A23: Project 25 rule | B23: 1 core + 1 supporting + 1 fun | C23: CCNA should be the core certification immediately after Security+, while HTB/PowerShell remain supporting/fun tracks to avoid burnout.

Sheet Projects
A1: ID | B1: Project | C1: Track | D1: Definition of Done | E1: Target | F1: XP | G1: Status
A2: P01 | B2: Homelab v1 | C2: Foundation | D2: AD + Windows + Linux + Kali environment | E2: Year 1 | F2: 100 | G2: Not Started
A3: P02 | B3: Python Network Scanner | C3: Foundation | D3: Scan hosts/ports and export results | E3: Year 1 | F3: 150 | G3: Not Started
A4: P03 | B4: Log Parser | C4: Blue Team | D4: Parse logs and flag indicators | E4: Year 1 | F4: 150 | G4: Not Started
A5: P04 | B5: Security Assessment Report | C5: Foundation | D5: Professional assessment of own lab | E5: Year 1 | F5: 200 | G5: Not Started
A6: P05 | B6: SOC Lab | C6: Blue Team | D6: SIEM + logs + alerting | E6: Year 2 | F6: 300 | G6: Not Started
A7: P06 | B7: Incident Response Simulation | C7: Blue Team | D7: Investigate simulated compromise | E7: Year 2 | F7: 350 | G7: Not Started
A8: P07 | B8: AD Pentest Lab | C8: Red Team | D8: Authorised AD assessment of own lab | E8: Year 3 | F8: 400 | G8: Not Started
A9: P08 | B9: Purple Team Exercise | C9: Purple Team | D9: Attack lab and validate detections | E9: Year 3 | F9: 400 | G9: Not Started
A10: P09 | B10: SOC Automation Engine | C10: Engineering | D10: IOC enrichment + threat intel + risk scoring | E10: Year 4 | F10: 500 | G10: Not Started
A11: P10 | B11: Enterprise Cyber Range | C11: Capstone | D11: Enterprise network + AD + SIEM + EDR | E11: Year 5 | F11: 800 | G11: Not Started
A12: P11 | B12: Final Purple Team Exercise | C12: Capstone | D12: Full attack + detection + IR + remediation | E12: Year 5 | F12: 1000 | G12: Not Started
A13: P12 | B13: PortSwigger Web Security Portfolio | C13: Red Team | D13: 20+ labs completed; 3 high-quality writeups covering SQLi/XSS/SSRF/auth | E13: Year 1 | F13: 250 | G13: Not Started
... A18: P17 | B18: Year 1 Career Portfolio | C18: Career | D18: CV + LinkedIn + GitHub + portfolio reviewed and updated | E18: Year 1 | F18: 100 | G18: Not Started

Sheet Weekly Tracker
A1: Week | B1: Start Date | C1: Main Goal | D1: Certification | E1: Lab | F1: Practice/HTB | G1: Coding | H1: Documentation | I1: Weekly XP | J1: Status
A2: 1 | I2: 0 | J2: Not Started
A3: 2 | I3: 0 | J3: Not Started
A4: 3 | I4: 0 | J4: Not Started
A5: 4 | I5: 0 | J5: Not Started
A6: 5 | I6: 0 | J6: Not Started
A7: 6 | I7: 0 | J7: Not Started
A8: 7 | I8: 0 | J8: Not Started
A9: 8 | I9: 0 | J9: Not Started
A10: 9 | I10: 0 | J10: Not Started
A11: 10 | I11: 0 | J11: Not Started
A12: 11 | I12: 0 | J12: Not Started
A13: 12 | I13: 0 | J13: Not Started
... A53: 52 | I53: 0 | J53: Not Started

Sheet Lists
A1: Status | B1: Priority | C1: Track
A2: Not Started | B2: Core | C2: Foundation
A3: In Progress | B3: Stretch | C3: Blue Team
A4: Done | C4: Red Team
C5: Purple Team
C6: Engineering

Sheet 12-Month Starter
A1: PROJECT 25 — 12-MONTH CYBERSECURITY STARTER
A2: Purpose: integrate your original 12-month ethical-hacking plan into the five-year roadmap, while keeping Blue Team/SOC, Red Team, web security, scripting, portfolio and career skills balanced.
A4: TOTAL | B4: DONE | C4: PROGRESS | D4: XP EARNED | E4: XP AVAILABLE | F4: MANDATORY | G4: OPTIONAL | H4: OPTIONAL DONE
A5: =COUNTA(A8:A54) -> 46 | B5: =COUNTIF(K8:K54,"Done") -> 0 | C5: =IF(B5=0,0,C5/B5) -> 0 | D5: =SUMIF(K8:K54,"Done",J8:J54) -> 0 | E5: =SUM(J8:J54) -> 4725 | F5: =COUNTIF(I8:I54,"Mandatory") -> 44 | G5: =COUNTIF(I8:I54,"Optional") -> 2 | H5: =SUMPRODUCT((I8:I54="Optional")*(K8:K54="Done")) -> 0
A7: Month | B7: Month # | C7: Track | D7: Skill / Topic | E7: What to Learn | F7: Practical Mission | G7: Primary Resource | H7: Portfolio Deliverable | I7: Priority | J7: XP | K7: Status
A8: 2026-09 | B8: 1 | C8: Foundations | D8: Networking + Cyber Basics | E8: TCP/IP, OSI, IPv4/IPv6, ports, DNS, DHCP, HTTP/HTTPS, VPN concepts | F8: Build a small virtual network and diagram it | G8: Network+ + lab notes | H8: Networking notes + diagram | I8: Mandatory | J8: 50 | K8: Not Started
A9: 2026-09 | B9: 1 | C9: Foundations | D9: Linux + CLI | E9: Filesystem, permissions, processes, package management, SSH, grep/find/curl | F9: Complete 25 Linux CLI exercises in your lab | G9: HTB Linux Fundamentals | H9: linux-basics.md | I9: Mandatory | J9: 50 | K9: Not Started
A10: 2026-09 | B10: 1 | C10: Foundations | D10: Windows + PowerShell | E10: Event Viewer, services, Defender, firewall, users/groups, PowerShell basics | F10: Create a Windows troubleshooting/security command cheat sheet | G10: Microsoft Learn + own lab | H10: windows-basics.md | I10: Mandatory | J10: 50 | K10: Not Started
A11: 2026-09 | B11: 1 | C11: Foundations | D11: Git/GitHub | E11: Git init/clone/add/commit/push, branches, README basics | F11: Create the Project 25 GitHub repo structure | G11: GitHub Docs | H11: repo-setup.md | I11: Mandatory | J11: 50 | K11: Not Started
A12: 2026-10 | B12: 2 | C12: Foundations | D12: Networking Deep Dive | E12: Subnetting, ARP, ICMP, TCP/UDP, NAT, routing, VLANs | F12: Capture and explain traffic with Wireshark | G12: Wireshark + Network+ | H12: wireshark-basics.md | I12: Mandatory | J12: 75 | K12: Not Started
A13: 2026-10 | B13: 2 | C13: Ethical Hacking | D13: Methodology | E13: Scope, rules of engagement, reconnaissance, enumeration, validation, reporting | F13: Write a safe penetration-testing methodology for your own lab | G13: HTB Penetration Testing Process | H13: pentest-methodology.md | I13: Mandatory | J13: 75 | K13: Not Started
A14: 2026-10 | B14: 2 | C14: Ethical Hacking | D14: Nmap | E14: Host discovery, service/version detection, safe enumeration concepts | F14: Scan only your lab and document findings | G14: Nmap docs + HTB | H14: nmap-lab.md | I14: Mandatory | J14: 75 | K14: Not Started
A15: 2026-10 | B15: 2 | C15: Ethical Hacking | D15: Bash | E15: Variables, loops, conditionals, functions, pipes, redirection | F15: Automate 3 repetitive lab tasks with Bash | G15: HTB Bash module | H15: bash-automation.md | I15: Mandatory | J15: 50 | K15: Not Started
A16: 2026-11 | B16: 3 | C16: Security | D16: Security Fundamentals | E16: CIA, IAM, AAA, risk, vulnerabilities, threats, controls, crypto basics | F16: Map common attacks to security controls | G16: Security+ | H16: security-fundamentals.md | I16: Mandatory | J16: 75 | K16: Not Started
A17: 2026-11 | B17: 3 | C17: Ethical Hacking | D17: Wireshark | E17: Filters, TCP streams, DNS/HTTP analysis, suspicious traffic concepts | F17: Investigate 5 packet captures and write findings | G17: Wireshark | H17: pcap-analysis.md | I17: Mandatory | J17: 75 | K17: Not Started
A18: 2026-11 | B18: 3 | C18: Ethical Hacking | D18: Metasploit concepts | E18: Understand modules, payloads, sessions, exploitation workflow in a lab | F18: Complete authorised lab exercises and document what occurred | G18: HTB / Metasploit docs | H18: metasploit-lab.md | I18: Mandatory | J18: 75 | K18: Not Started
A19: 2026-11 | B19: 3 | C19: Blue Team | D19: Windows Logs | E19: Security, System, PowerShell and authentication events | F19: Build a Windows event log cheat sheet | G19: Microsoft Learn | H19: windows-event-logs.md | I19: Mandatory | J19: 75 | K19: Not Started
... A53: 2027-08 | B53: 12 | C53: Career | D53: Year 1 Review | E53: Skills, portfolio, certs, gaps, next-year targets | F53: Perform a formal Project 25 quarterly/annual review | G53: Project 25 | H53: year1-review.md | I53: Mandatory | J53: 100 | K53: Not Started
A56: GAMIFIED RULE: set a mission to Done only when you can demonstrate the skill or produce the stated deliverable. XP is awarded for evidence-backed completion; do not award yourself XP for simply watching a course.
A58: MICROSOFT / RDP ADD-ON TRACK
A59: Month | B59: Month # | C59: Track | D59: Skill / Topic | E59: What to Learn | F59: Practical Mission | G59: Primary Resource | H59: Portfolio Deliverable | I59: Priority | J59: XP | K59: Status
A60: 2026-09 | B60: 1 | C60: Microsoft / RDP | D60: RDP Security & Architecture | E60: RDP services, NLA, sessions, Windows Firewall, authentication flow | F60: Map an RDP environment and create a secure remote-access checklist | G60: Microsoft Learn | H60: rdp-security-checklist.md | I60: Mandatory | J60: 75 | K60: Not Started
A61: 2026-10 | B61: 2 | C61: Microsoft / Windows | D61: Windows Server Administration | E61: Roles, services, Event Viewer, local security, PowerShell administration | F61: Build Windows Server lab and document admin/security commands | G61: Microsoft Learn | H61: windows-server-admin.md | I61: Mandatory | J61: 75 | K61: Not Started
A62: 2026-11 | B62: 3 | C62: Microsoft / AD | D62: Active Directory DS | E62: Domains, OUs, users, groups, GPO, DNS, domain controllers | F62: Build AD lab with GPOs and role-based groups | G62: Microsoft Learn | H62: ad-ds-lab.md | I62: Mandatory | J62: 100 | K62: Not Started
A63: 2026-12 | B63: 4 | C63: Microsoft / Entra | D63: Entra ID Fundamentals | E63: Entra ID, MFA, Conditional Access, RBAC, hybrid identity | F63: Complete SC-900-aligned Entra labs/notes | G63: Microsoft Learn SC-900 | H63: entra-sc900.md | I63: Mandatory | J63: 75 | K63: Not Started
A64: 2027-01 | B64: 5 | C64: Microsoft / Azure | D64: Azure Fundamentals | E64: Subscriptions, resources, VNets, NSGs, VMs, storage, identity | F64: Deploy a small Azure lab environment securely | G64: Microsoft Learn AZ-900/AZ-104 | H64: azure-fundamentals-lab.md | I64: Mandatory | J64: 100 | K64: Not Started
A65: 2027-02 | B65: 6 | C65: Microsoft / Identity | D65: Hybrid Identity | E65: AD ↔ Entra concepts, device identity, sync concepts | F65: Create a hybrid identity architecture diagram | G65: Microsoft Learn SC-300 | H65: hybrid-identity-diagram.md | I65: Mandatory | J65: 100 | K65: Not Started
A66: 2027-03 | B66: 7 | C66: Microsoft / SOC | D66: Sentinel + KQL | E66: Logs, incidents, KQL queries, analytics rules | F66: Ingest Windows logs and write 10 KQL queries | G66: Microsoft Learn SC-200 | H66: sentinel-kql-lab.md | I66: Mandatory | J66: 125 | K66: Not Started
A67: 2027-04 | B67: 8 | C67: Microsoft / Identity | D67: Conditional Access + PIM | E67: MFA, Conditional Access, least privilege, PIM, access reviews | F67: Design a secure identity baseline | G67: Microsoft Learn SC-300 | H67: entra-security-baseline.md | I67: Mandatory | J67: 125 | K67: Not Started
A68: 2027-05 | B68: 9 | C68: Microsoft / Endpoint | D68: Intune / AVD concepts | E68: Intune, Entra device identity, Azure Virtual Desktop, Windows 365 | F68: Document a secure managed endpoint + remote desktop architecture | G68: Microsoft Learn MD-102 | H68: endpoint-rdp-architecture.md | I68: Mandatory | J68: 100 | K68: Not Started
A69: 2027-06 | B69: 10 | C69: Microsoft / Security | D69: Defender XDR + IR | E69: Defender for Endpoint, Defender for Identity, Sentinel investigations | F69: Run a Microsoft-focused incident response simulation | G69: Microsoft Learn SC-200 | H69: microsoft-ir-lab.md | I69: Mandatory | J69: 150 | K69: Not Started
A70: 2027-07 | B70: 11 | C70: Microsoft / AD Security | D70: AD Attack Detection | E70: Kerberos/NTLM concepts and defensive telemetry | F70: Map AD attack techniques to Microsoft logs/detections | G70: MITRE + Microsoft Learn | H70: ad-attack-detection.md | I70: Mandatory | J70: 150 | K70: Not Started
A71: 2027-08 | B71: 12 | C71: Microsoft / Portfolio | D71: Enterprise Microsoft Case Study | E71: RDP + Windows Server + AD + Entra + Azure + security | F71: Publish a sanitized enterprise architecture/security case study | G71: Microsoft Learn + GitHub | H71: microsoft-case-study.md | I71: Mandatory | J71: 200 | K71: Not Started
A73: CCNA MINI-TRACK — RIGHT AFTER SECURITY+
A74: 2027-02 | B74: After S+ | C74: Networking | D74: CCNA Routing & Switching Core | E74: VLANs, trunking, routing, IPv4/IPv6, STP, EtherChannel, wireless fundamentals | F74: Build a Packet Tracer/GNS3 lab with VLANs and inter-VLAN routing | G74: Cisco CCNA | H74: ccna-lab-01.md | I74: Mandatory | J74: 100 | K74: Not Started
A75: 2027-03 | B75: After S+ | C75: Networking | D75: CCNA Network Services & Security | E75: NAT, DHCP, DNS, ACLs, SSH, device hardening, basic automation | F75: Configure ACLs, SSH and secure management in the lab | G75: Cisco CCNA | H75: ccna-security-01.md | I75: Mandatory | J75: 100 | K75: Not Started
A76: 2027-04 | B76: After S+ | C76: Networking | D76: CCNA Review + Exam | E76: Troubleshooting, subnetting, wireless, automation concepts, weak domains | F76: Take practice exams; sit CCNA when readiness is demonstrated | G76: Cisco CCNA | H76: cert-ccna.md | I76: Mandatory | J76: 125 | K76: Not Started
A77: Rule | B77: Important | C77: Networking | D77: Don't let CCNA replace the cybersecurity track | E77: CCNA is a strategic networking depth milestone; continue HTB/SOC/PowerShell alongside it at sustainable intensity | F77: Keep networking labs tied to security use-cases | G77: Project 25 | H77: ccna-security-integration.md | I77: Mandatory | J77: 50 | K77: Not Started

Sheet GitHub Portfolio
A1: PROJECT 25 — GITHUB PORTFOLIO ARCHITECTURE
A2: Goal: make your GitHub prove capability, not just show certificates. Every major project should have a README, architecture/diagrams, reproducible steps, evidence, limitations, remediation and a clear ethical scope.
A4: Folder / Repo | B4: Purpose | C4: Example Contents | D4: Public? | E4: Status | F4: Rule | H4: README TEMPLATE | I4: Required? | J4: What Good Looks Like
A5: 00-profile | B5: Professional landing page | C5: Bio, skills, certs, goals, featured projects | D5: YES | E5: Not Started | F5: Keep concise; link to best work | H5: Problem / Objective | I5: YES | J5: What were you trying to solve?
A6: 01-foundations | B6: Networking/Linux/Windows fundamentals | C6: Lab notes, diagrams, command references | D6: YES | E6: Not Started | F6: No credentials or client data | H6: Scope / Ethics | I6: YES | J6: Exactly what systems were authorised?
A7: 02-python-security | B7: Security automation code | C7: Scanners, parsers, API tools, enrichment | D7: YES | E7: Not Started | F7: Use safe lab targets only | H7: Environment | I7: YES | J7: Lab setup, versions, topology
A8: 03-blue-team | B8: SOC and defensive work | C8: KQL, detections, hunting, IR reports | D8: YES | E8: Not Started | F8: Sanitise all evidence | H8: Methodology | I8: YES | J8: How you approached the assessment
A9: 04-red-team | B9: Offensive learning | C9: CTF writeups, lab pentests, methodology | D9: YES | E9: Not Started | F9: Only authorised targets | H9: Evidence | I9: YES | J9: Screenshots, logs, commands, sanitized output
A10: 05-web-security | B10: Web security research | C10: PortSwigger writeups, OWASP notes, Burp workflows | D10: YES | E10: Not Started | F10: Never publish live target secrets | H10: Findings | I10: YES | J10: Impact + severity + evidence
A11: 06-active-directory | B11: AD security lab | C11: Diagrams, attack paths, detections, hardening | D11: YES | E11: Not Started | F11: Use lab identities/assets | H11: Detection / Defence | I11: YES | J11: How the issue can be detected/prevented
A12: 07-purple-team | B12: Attack/detect validation | C12: ATT&CK mappings, detection tests, gap analysis | D12: YES | E12: Not Started | F12: Show both attacker and defender view | H12: Remediation | I12: YES | J12: Concrete fixes
A13: 08-homelab | B13: Infrastructure documentation | C13: Topology, build notes, IaC/scripts where safe | D13: YES | E13: Not Started | F13: Remove real IPs, passwords and internal names | H13: Lessons Learned | I13: YES | J13: What changed in your understanding
A14: 09-reports | B14: Professional-style reports | C14: Pentest, IR, executive summaries | D14: YES | E14: Not Started | F14: Use fictional/sanitised targets | H14: Reproduction | I14: YES | J14: Steps another learner can repeat safely
A15: 10-research | B15: Deep dives | C15: Technical research, experiments, lessons learned | D15: YES | E15: Not Started | F15: Cite sources | H15: References | I15: YES | J15: Official docs / standards / sources
A16: 99-archive | B16: Retired projects | C16: Old versions and lessons learned | D16: YES | E16: Not Started | F16: Archive rather than delete learning
A18: MICROSOFT / RDP PORTFOLIO — ADD THESE TO YOUR GITHUB STRUCTURE
A19: Repo / Folder | B19: What it proves | C19: Example Contents | D19: Public? | E19: Status | F19: Rule | G19: README Template | H19: Required? | I19: Best Evidence | J19: Primary Tech
A20: 11-microsoft-rdp | B20: Windows/RDP administration and security | C20: RDP architecture, hardening, logging, troubleshooting | D20: YES | E20: Not Started | F20: Never publish client data | G20: Problem → Architecture → Security controls → Validation → Lessons | H20: YES | I20: Diagrams + sanitized logs | J20: RDP / Windows
A21: 12-active-directory | B21: AD administration + security | C21: OUs, GPOs, identity design, attack detection | D21: YES | E21: Not Started | F21: Lab identities/assets only | G21: Scope → Lab → Design → Test → Detection → Remediation | H21: YES | I21: AD diagrams + detections | J21: AD DS / PowerShell
A22: 13-entra-id | B22: Cloud identity and access | C22: MFA, Conditional Access, RBAC, PIM, access reviews | D22: YES | E22: Not Started | F22: Never expose tenant IDs/secrets | G22: Identity model → Policies → Test cases → Security impact | H22: YES | I22: Policy screenshots sanitized | J22: Entra ID / SC-300
A23: 14-azure | B23: Azure administration + security | C23: VNets, NSGs, VMs, storage, monitoring, governance | D23: YES | E23: Not Started | F23: No secrets / keys / IPs | G23: Architecture → Deployment → Security → Monitoring → Cost | H23: YES | I23: Architecture diagram + configs | J23: Azure / AZ-104
A24: 15-microsoft-soc | B24: Microsoft SOC/security engineering | C24: Sentinel, KQL, Defender XDR, hunting, detections | D24: YES | E24: Not Started | F24: Use lab telemetry only | G24: Scenario → Telemetry → Query → Detection → Response | H24: YES | I24: KQL + alert evidence | J24: Sentinel / Defender / KQL
A25: 16-intune-endpoint | B25: Endpoint and remote-work security | C25: Intune, Defender for Endpoint, Windows 365/AVD concepts | D25: YES | E25: Not Started | F25: No client device details | G25: Device model → Policy → Security → Validation | H25: YES | I25: Policy diagrams + screenshots | J25: Intune / MD-102

Sheet Resources
A1: PROJECT 25 — CORE RESOURCES & CURRENT REFERENCE LINKS
A3: Area | B3: Resource | C3: Why Use It | D3: Source URL
A4: SOC | B4: HTB SOC Analyst path | C4: Practical progression through traffic analysis, SIEM, DFIR and reporting | D4: https://academy.hackthebox.com/catalogue/paths
A5: Pentesting | B5: HTB Penetration Tester path | C5: Structured recon → enumeration → exploitation → reporting pathway | D5: https://academy.hackthebox.com/path/preview/penetration-tester
A6: Web Security | B6: PortSwigger Web Security Academy | C6: Free, hands-on web security labs covering SQLi, XSS, SSRF, access control and more | D6: https://portswigger.net/web-security
A7: Blue Team | B7: Microsoft SC-200 study guide | C7: Current Microsoft security-operations objectives including triage, incident response, threat hunting and detections | D7: https://learn.microsoft.com/en-us/credentials/certifications/resources/study-guides/sc-200
A8: Cybersecurity Framework | B8: MITRE ATT&CK | C8: Map offensive behaviour to defender detections and threat hunting | D8: https://attack.mitre.org/
A9: Networking | B9: Wireshark | C9: Traffic capture and analysis | D9: https://www.wireshark.org/
A10: Programming | B10: Python Docs | C10: Reference for automation and security tooling | D10: https://docs.python.org/3/
A11: Web | B11: OWASP | C11: Web application security guidance and Top 10 | D11: https://owasp.org/
A12: Linux | B12: HTB Linux Fundamentals | C12: Hands-on Linux command line foundations | D12: https://academy.hackthebox.com/
A13: Portfolio | B13: GitHub Docs | C13: Version control, README and project publishing guidance | D13: https://docs.github.com/
A15: Certification Guidance | B15: Priority order | C15: Network+ → Security+ → CySA+/SC-200 → OSCP+ | D15: Project 25 prioritises practical capability over certificate count.
... A37: Reverse Engineering | B37: Ghidra Beginner Guide | C37: Official beginner-oriented training material for learning Ghidra | D37: https://github.com/NationalSecurityAgency/ghidra/blob/master/GhidraDocs/GhidraClass/Beginner/Introduction_to_Ghidra_Student_Guide.html

Sheet Microsoft Track
A1: PROJECT 25 — MICROSOFT / RDP / ENTRA SECURITY TRACK
A2: Built around your real RDP/Windows support experience. Goal: become strong in Windows Server, Active Directory, Microsoft Entra ID, Azure, Defender, Sentinel and Microsoft identity/security operations.
A4: TOTAL MISSIONS | B4: DONE | C4: PROGRESS | D4: XP EARNED | E4: XP AVAILABLE | F4: CERTS TARGETED
A5: =COUNTA(A9:A60) -> 42 | B5: =COUNTIF(K9:K60,"Done") -> 0 | C5: =IFERROR(B5/A5,0) -> 0 | D5: =SUMIF(K9:K60,"Done",J9:J60) -> 0 | E5: =SUM(J9:J60) -> 4250 | F5: =COUNTIF(I9:I60,"<>") -> 20
A8: Month | B8: Phase | C8: Area | D8: Skill / Mission | E8: What to Learn | F8: Practical Mission | G8: Microsoft Resource | H8: GitHub Deliverable | I8: Certification | J8: XP | K8: Status | L8: Notes
A9: 2026-09 | B9: Foundation | C9: RDP / Windows | D9: RDP internals | E9: RDP architecture, sessions, NLA, ports, Remote Desktop Services, authentication flow | F9: Map an RDP session from client to host in your lab and document security controls | G9: Microsoft Learn — Remote Desktop Services | H9: rdp-architecture.md | J9: 50 | K9: Not Started | L9: Use only lab/authorised systems
A10: 2026-09 | B10: Foundation | C10: Windows Server | D10: Server administration basics | E10: Server roles, services, Event Viewer, local users/groups, scheduled tasks, services | F10: Build a Windows Server VM and document 20 admin/security commands | G10: Microsoft Learn — Windows Server | H10: windows-server-basics.md | J10: 50 | K10: Not Started
A11: 2026-10 | B11: Foundation | C11: Active Directory | D11: AD DS fundamentals | E11: Domain controllers, forests, domains, OUs, users, groups, GPO, DNS | F11: Build a small AD lab with DC01 + two clients; create OUs, groups and GPOs | G11: Microsoft Learn — AD DS | H11: ad-lab-build.md | J11: 75 | K11: Not Started
A12: 2026-10 | B12: Foundation | C12: PowerShell | D12: Remote administration | E12: Get-Command, Get-Service, Get-WinEvent, remoting concepts, error handling | F12: Create a safe PowerShell admin toolkit for your lab | G12: Microsoft Learn — PowerShell | H12: powershell-admin-toolkit.md | J12: 75 | K12: Not Started
A13: 2026-11 | B13: Identity | C13: Entra ID | D13: Microsoft Entra basics | E13: Tenants, identities, roles, groups, MFA, Conditional Access, hybrid identity | F13: Create a Microsoft Entra study tenant/lab plan and map on-prem AD concepts to Entra | G13: Microsoft Learn — Introduction to Microsoft Entra | H13: entra-basics.md | I13: SC-900 | J13: 75 | K13: Not Started | L13: Entra ID is the current name for Azure AD
A14: 2026-11 | B14: Identity | C14: Microsoft Security | D14: SCI fundamentals | E14: Zero Trust, identity as security perimeter, Defender, Sentinel, Purview concepts | F14: Map Microsoft security services to common helpdesk/security incidents | G14: Microsoft Learn — SC-900 | H14: microsoft-security-map.md | I14: SC-900 | J14: 75 | K14: Not Started
A15: 2026-12 | B15: Identity | C15: Entra ID | D15: Authentication & access | E15: MFA, SSPR, Conditional Access, RBAC, PIM, access reviews | F15: Design a secure sign-in policy set for a fictional SMB | G15: Microsoft Learn — SC-900 / Entra | H15: entra-access-design.md | I15: SC-900 | J15: 75 | K15: Not Started
A16: 2027-01 | B16: Cloud | C16: Azure | D16: Azure fundamentals | E16: Subscriptions, resource groups, regions, VNets, NSGs, storage, VMs | F16: Deploy a small Azure lab VM and document the network/security path | G16: Microsoft Learn — Azure Fundamentals | H16: azure-lab.md | I16: AZ-900 | J16: 100 | K16: Not Started | L16: AZ-900 is optional if you are comfortable with Azure fundamentals
A17: 2027-01 | B17: Cloud | C17: Azure Admin | D17: Compute + networking | E17: VMs, VNets, subnets, NSGs, public/private IPs, storage, monitoring | F17: Build a secure Azure test environment using least exposure | G17: Microsoft Learn — AZ-104 | H17: azure-vm-network.md | I17: AZ-104 | J17: 125 | K17: Not Started
A18: 2027-02 | B18: Identity | C18: Hybrid Identity | D18: AD ↔ Entra concepts | E18: Entra Connect/Cloud Sync concepts, identities, device identity, hybrid join | F18: Create a diagram showing user/device identity flow in a hybrid environment | G18: Microsoft Learn — SC-300 | H18: hybrid-identity.md | I18: SC-300 | J18: 125 | K18: Not Started
A19: 2027-02 | B19: Security | C19: Microsoft Defender | D19: Defender ecosystem | E19: Defender for Endpoint, Defender XDR, Defender for Identity, Defender for Cloud concepts | F19: Map a Windows incident to the relevant Microsoft Defender product | G19: Microsoft Learn — SC-900 / SC-200 | H19: defender-product-map.md | I19: SC-200 | J19: 100 | K19: Not Started
A20: 2027-03 | B20: Security | C20: Sentinel | D20: SIEM fundamentals | E20: Connectors, analytics rules, incidents, workbooks, automation, KQL | F20: Ingest Windows/security logs into a Sentinel lab and build one alert | G20: Microsoft Learn — SC-200 | H20: sentinel-lab.md | I20: SC-200 | J20: 150 | K20: Not Started
A21: 2027-03 | B21: Security | C21: KQL | D21: Microsoft security hunting | E21: where, project, summarize, extend, joins, time filtering | F21: Write 10 KQL queries against lab data and explain each query | G21: Microsoft Learn — KQL / SC-200 | H21: kql-microsoft.md | I21: SC-200 | J21: 100 | K21: Not Started
A22: 2027-04 | B22: Identity | C22: Entra Security | D22: Conditional Access | E22: Named locations, device/user conditions, risk concepts, MFA, session controls | F22: Design and document a Conditional Access baseline for a fictional tenant | G22: Microsoft Learn — SC-300 | H22: conditional-access-baseline.md | I22: SC-300 | J22: 125 | K22: Not Started
A23: 2027-04 | B23: Identity | C23: Entra Governance | D23: Privileged Identity | E23: RBAC, PIM, access reviews, least privilege, identity governance | F23: Create a privileged-access model for the lab | G23: Microsoft Learn — SC-300 | H23: entra-pim-model.md | I23: SC-300 | J23: 100 | K23: Not Started
A24: 2027-05 | B24: Cloud | C24: Azure Admin | D24: Azure monitoring + governance | E24: Azure Monitor, Log Analytics, resource locks, Policy, tags, cost/security basics | F24: Create a governance checklist for your Azure lab | G24: Microsoft Learn — AZ-104 | H24: azure-governance.md | I24: AZ-104 | J24: 100 | K24: Not Started
A25: 2027-05 | B25: Endpoint | C25: Intune / Windows 365 | D25: Modern endpoint concepts | E25: Intune, Entra device identity, Windows 365, Azure Virtual Desktop concepts | F25: Document how a managed Windows endpoint connects to identity and security controls | G25: Microsoft Learn — MD-102 | H25: modern-endpoint.md | I25: MD-102 | J25: 100 | K25: Not Started | L25: MD-102 is a strategic optional cert for your IT-to-security path
A26: 2027-06 | B26: Security | C26: Microsoft SOC | D26: Incident response | E26: Triage, incidents, Defender XDR, Sentinel investigations, response actions | F26: Run a simulated compromise and investigate it using Microsoft telemetry concepts | G26: Microsoft Learn — SC-200 | H26: microsoft-ir.md | I26: SC-200 | J26: 150 | K26: Not Started
A27: 2027-06 | B27: RDP / Security | C27: RDP Hardening | D27: Secure remote access | E27: NLA, MFA/RD Gateway concepts, firewall rules, lockout policy, logging, patching, privileged access | F27: Create an RDP hardening standard for a fictional client environment | G27: Microsoft security guidance | H27: rdp-hardening-standard.md | J27: 125 | K27: Not Started | L27: Do not expose lab RDP directly to the internet
A28: 2027-07 | B28: Windows | C28: Windows Security | D28: Sysinternals | E28: Autoruns, Process Explorer, TCPView, PsExec concepts, Procmon, Sigcheck | F28: Use Sysinternals in your lab to investigate a simulated suspicious endpoint | G28: Microsoft Sysinternals | H28: sysinternals-investigation.md | J28: 125 | K28: Not Started
A29: 2027-07 | B29: Identity | C29: AD Security | D29: Kerberos + identity attacks | E29: Kerberos/NTLM concepts, service accounts, delegation, authentication telemetry | F29: Map common AD attack techniques to Microsoft detection points | G29: Microsoft Learn + MITRE ATT&CK | H29: ad-identity-detections.md | I29: SC-300 / SC-200 | J29: 150 | K29: Not Started
A30: 2027-08 | B30: Career | C30: Microsoft Portfolio | D30: Enterprise case study | E30: Combine RDP, Windows Server, AD, Entra, Azure and security into one scenario | F30: Publish a fully sanitised architecture + security case study | G30: GitHub + Microsoft Learn | H30: microsoft-enterprise-case-study.md | J30: 200 | K30: Not Started
A31: 2027-09 | B31: Certification | C31: Microsoft Identity | D31: SC-300 readiness | E31: Review identity lifecycle, authentication, authorization, governance, hybrid identity | F31: Complete practice assessment and close knowledge gaps | G31: Microsoft Learn — SC-300 | H31: sc300-readiness.md | I31: SC-300 | J31: 100 | K31: Not Started
A32: 2027-10 | B32: Certification | C32: Microsoft Security | D32: SC-200 readiness | E32: Triage, KQL, Sentinel, Defender XDR, threat hunting, detection engineering | F32: Complete SC-200 practice assessment and build a final detection pack | G32: Microsoft Learn — SC-200 | H32: sc200-readiness.md | I32: SC-200 | J32: 125 | K32: Not Started
A33: 2027-11 | B33: Certification | C33: Azure | D33: AZ-104 readiness | E33: Compute, networking, storage, identity, governance, monitoring | F33: Complete AZ-104 practice assessment and deploy final Azure lab | G33: Microsoft Learn — AZ-104 | H33: az104-readiness.md | I33: AZ-104 | J33: 125 | K33: Not Started
A34: 2028-01 | B34: Advanced | C34: Microsoft Security | D34: Detection engineering | E34: Sigma-style thinking, KQL, Defender/Sentinel detections, ATT&CK mapping | F34: Build 10 Microsoft-focused detections for your lab | G34: SC-200 + MITRE | H34: microsoft-detections-v1.md | J34: 175 | K34: Not Started
A35: 2028-03 | B35: Advanced | C35: Azure Security | D35: Cloud security engineering | E35: Defender for Cloud, Key Vault, NSGs, workload identity, secure VM design | F35: Perform a cloud security review of your Azure lab | G35: Microsoft Learn | H35: azure-security-review.md | J35: 175 | K35: Not Started
A36: 2028-06 | B36: Advanced | C36: Microsoft 365 | D36: Tenant security | E36: Entra, Defender XDR, Purview, Secure Score concepts | F36: Create a fictional Microsoft 365 security baseline | G36: Microsoft Learn — MS-102 | H36: m365-security-baseline.md | I36: MS-102 | J36: 175 | K36: Not Started | L36: Optional long-term M365 track
A37: 2028-09 | B37: Advanced | C37: Endpoint | D37: Endpoint security | E37: Intune policies, Defender for Endpoint, device compliance, app control | F37: Secure a Windows endpoint policy set in your lab | G37: Microsoft Learn — MD-102 | H37: endpoint-security-baseline.md | I37: MD-102 | J37: 175 | K37: Not Started
A38: 2029-03 | B38: Purple Team | C38: Microsoft Attack/Defend | D38: AD + Entra attack detection | E38: Attack-path thinking across on-prem AD and Entra; identity telemetry | F38: Run an authorised identity attack simulation and validate detections | G38: HTB + Microsoft Learn + MITRE | H38: ad-entra-purple-team.md | J38: 250 | K38: Not Started | L38: Lab only
A39: 2030-01 | B39: Engineering | C39: Microsoft Security Automation | D39: Graph/API automation | E39: Microsoft Graph concepts, REST APIs, PowerShell/Python automation, response workflows | F39: Build a safe lab automation tool for alert enrichment or account checks | G39: Microsoft Graph + Python/PowerShell | H39: microsoft-security-automation.md | J39: 250 | K39: Not Started
A40: 2031-04 | B40: Capstone | C40: Enterprise Microsoft Security | D40: Full hybrid environment | E40: Windows Server + AD + Entra + Azure + Sentinel + Defender + RDP | F40: Build and document the Project 25 Microsoft enterprise cyber range | G40: Microsoft Learn + own lab | H40: project25-microsoft-cyber-range.md | J40: 350 | K40: Not Started | L40: Capstone
A42: MICROSOFT CERTIFICATION LADDER — RECOMMENDED ORDER
A43: Order | B43: Credential | C43: Why it fits you | D43: Priority | E43: Recommended Timing | F43: Status | G43: Current Microsoft focus
A44: 1 | B44: SC-900 — Security, Compliance, and Identity Fundamentals | C44: Fast foundation for Entra, Defender, Sentinel and Microsoft security vocabulary | D44: HIGH | E44: Late 2026 / Early 2027 | F44: Not Started | G44: Entra ID, Zero Trust, Defender, Sentinel, Purview
...

Sheet My Certifications
A1: PROJECT 25 — MY CERTIFICATION WALLET | M1: CUSTOM CERT STATS
A2: Add any certification you discover as your career develops. This is your flexible wishlist/tracker — it does not change the core roadmap unless you decide it should.
M3: Planned / Studying | N3: =COUNTIF(F5:F24,"Planned")+COUNTIF(F5:F24,"Studying")+COUNTIF(F5:F24,"Booked") -> 20
A4: Certification | B4: Provider | C4: Domain | D4: Target Age | E4: Priority | F4: Status | G4: Target Date | H4: Exam / Renewal | I4: XP | J4: Link / Source | K4: Notes | M4: Completed | N4: =COUNTIF(F5:F24,"Completed") -> 0
E5: High | F5: Planned | I5: 250 | M5: Total XP | N5: =SUM(I5:I24) -> 3050
E6: Medium | F6: Planned | I6: 150 | M6: High+ Priority | N6: =COUNTIF(E5:E24,"Critical")+COUNTIF(E5:E24,"Very High")+COUNTIF(E5:E24,"High") -> 1
E7: Low | F7: Planned | I7: 100 | M7: Slots Used | N7: =COUNTA(A5:A24) -> 0
E8: Medium | F8: Planned | I8: 150
E9: Medium | F9: Planned | I9: 150
E10: Medium | F10: Planned | I10: 150
E11: Medium | F11: Planned | I11: 150
E12: Medium | F12: Planned | I12: 150
E13: Medium | F13: Planned | I13: 150
E14: Medium | F14: Planned | I14: 150
E15: Medium | F15: Planned | I15: 150
E16: Medium | F16: Planned | I16: 150
E17: Medium | F17: Planned | I17: 150
E18: Medium | F18: Planned | I18: 150
E19: Medium | F19: Planned | I19: 150
... E24: Medium | F24: Planned | I24: 150
A25: Cisco CCNA | B25: Cisco | C25: Networking / Security | D25: 20–21 | E25: Very High | F25: Planned | G25: Mid/late 2027 | I25: 250 | J25: https://www.cisco.com/site/us/en/learn/training-certifications/exams/ccna.html | K25: Target immediately after Security+; use the current exam version when you are ready.
A26: Microsoft SC-500 | B26: Microsoft | C26: Cloud / AI Security | D26: 23–25 | E26: High | F26: Planned | I26: 300 | J26: https://learn.microsoft.com/en-us/credentials/certifications/cloud-and-ai-security-engineer-associate/ | K26: Future cloud-security path; revisit exam status before committing.
A27: Malware Analysis / RE Certification | B27: TBD | C27: DFIR / Reverse Engineering | D27: 25–27 | E27: Low | F27: Planned | I27: 300 | K27: Not required. Pick based on the market and training available at the time.
A28: Custom Future Certification | B28: Add provider | C28: Add domain | D28: 26+ | E28: Medium | F28: Planned | I28: 150 | K28: Use this row for something you discover later.

Sheet Scripting & Dev
A1: PROJECT 25 — SCRIPTING, AUTOMATION & FUTURE SOFTWARE DEVELOPMENT
A2: Security-first programming now; broader software development later. PowerShell/Bash are operational tools, Python is your primary security language, and Year 6+ adds C# / C++ / Java according to career needs.
A4: Phase | B4: Timeframe | C4: Language / Tool | D4: Skill | E4: Practical Mission | F4: Portfolio Deliverable | G4: Track | H4: Status | I4: XP | J4: Notes
A5: Now | B5: 2026-09 | C5: PowerShell | D5: CLI + discovery | E5: Use Get-Command/Get-Help/Get-Process/Get-Service and explain each | F5: powershell-basics.md | G5: Engineering | H5: Not Started | I5: 50
A6: Now | B6: 2026-09 | C6: PowerShell | D6: Objects + pipeline | E6: Build a script that inventories services/processes in your lab | F6: powershell-objects-pipeline.md | G6: Engineering | H6: Not Started | I6: 75
A7: Now | B7: 2026-10 | C7: PowerShell | D7: Files + permissions | E7: Write a safe file-audit script for your lab | F7: powershell-file-audit.ps1 | G7: Engineering | H7: Not Started | I7: 75
A8: Now | B8: 2026-10 | C8: PowerShell | D8: Event logs | E8: Build a Windows Event Log triage script | F8: powershell-event-triage.ps1 | G8: Blue Team | H8: Not Started | I8: 100
A9: Now | B9: 2026-11 | C9: PowerShell | D9: Remoting concepts | E9: Document WinRM/PowerShell Remoting and safe lab use | F9: powershell-remoting-notes.md | G9: Engineering | H9: Not Started | I9: 75
A10: Now | B10: 2026-11 | C10: Bash | D10: Linux automation | E10: Create a system-health script for a Linux VM | F10: linux-health-check.sh | G10: Engineering | H10: Not Started | I10: 75
A11: Now | B11: 2026-12 | C11: Python | D11: Core syntax | E11: Build 3 tiny utilities: args, files, JSON | F11: python-foundations.md | G11: Engineering | H11: Not Started | I11: 50
A12: Now | B12: 2027-01 | C12: Python | D12: Networking | E12: Build an authorised lab port/service scanner | F12: python-lab-scanner | G12: Red Team | H12: Not Started | I12: 100
A13: Now | B13: 2027-02 | C13: Python | D13: Logs / regex | E13: Parse Windows or Linux logs and extract useful fields | F13: python-log-parser | G13: Blue Team | H13: Not Started | I13: 100
A14: Now | B14: 2027-03 | C14: Python | D14: APIs | E14: Consume a public security API and enrich an IOC in a lab workflow | F14: python-api-enricher | G14: Blue Team | H14: Not Started | I14: 100
A15: Now | B15: 2027-04 | C15: PowerShell | D15: Security administration | E15: Build a lab toolkit for account/service/event checks | F15: powershell-security-toolkit | G15: Blue Team | H15: Not Started | I15: 125
A16: Now | B16: 2027-05 | C16: Python | D16: Automation | E16: Turn a repeatable SOC task into a command-line tool | F16: soc-automation-cli | G16: Engineering | H16: Not Started | I16: 150
... A26: Year 5 | B26: 2031-04 | C26: Python | D26: Capstone | E26: Build a security automation component for the Project 25 cyber range | F26: project25-security-automation | G26: Engineering | H26: Not Started | I26: 300
A27: Year 6+ | B27: Post-2031 | C27: C# | D27: Microsoft software development | E27: Learn C#/.NET fundamentals and build a small admin/security application | F27: csharp-security-app | G27: Software Development | H27: Not Started | I27: 200 | J27: Recommended first general-purpose language after Python due Microsoft ecosystem
A28: Year 6+ | B28: Post-2031 | C28: C++ | D28: Systems programming | E28: Learn memory, pointers, compilation and a small systems/security project | F28: cpp-systems-project | G28: Software Development | H28: Not Started | I28: 250 | J28: Use after fundamentals are solid
A29: Year 6+ | B29: Post-2031 | C29: Java | D29: Enterprise development | E29: Learn OOP, APIs and a small backend application | F29: java-enterprise-project | G29: Software Development | H29: Not Started | I29: 200 | J29: Optional; pick based on career direction
A30: Year 6+ | B30: Post-2031 | C30: Software Engineering | D30: Architecture | E30: Git workflows, testing, CI/CD, APIs, databases, secure coding | F30: software-engineering-foundations | G30: Software Development | H30: Not Started | I30: 300 | J30: Year 6+ objective, not a current priority
A31: Year 6+ | B31: 2032 | C31: C | D31: Systems fundamentals | E31: Learn memory, pointers, structs, compilation and debugging basics | F31: c-systems-foundations | G31: Software Development | H31: Planned | I31: 200 | J31: Bridge into malware RE
A32: Year 6+ | B32: 2032 | C32: C++ | D32: Systems / Windows | E32: Build a small Windows systems utility and study executable structure | F32: cpp-windows-systems-project | G32: Software Development | H32: Planned | I32: 250 | J32: Supports reverse engineering
A33: Year 6+ | B33: 2032 | C33: Assembly | D33: x86-64 fundamentals | E33: Registers, stack, calling conventions, control flow and common instructions | F33: x64-assembly-notes.md | G33: Reverse Engineering | H33: Planned | I33: 300 | J33: Core RE prerequisite
A34: Year 6+ | B34: 2032 | C34: Ghidra | D34: Static reverse engineering | E34: Analyse benign training binaries and document functions/control flow | F34: ghidra-analysis-project | G34: Reverse Engineering | H34: Planned | I34: 350 | J34: Use official Ghidra material
A35: Year 6+ | B35: 2032 | C35: x64dbg / WinDbg | D35: Dynamic analysis | E35: Set breakpoints, inspect registers/memory, trace execution in a safe lab | F35: debugger-analysis-project | G35: Reverse Engineering | H35: Planned | I35: 350 | J35: Lab-only
A36: Year 6+ | B36: 2032 | C36: REMnux | D36: Malware analysis | E36: Build an isolated analysis environment and perform static/dynamic triage | F36: remnux-malware-lab | G36: Blue Team | H36: Planned | I36: 350 | J36: Use benign/CTF samples only
A37: Year 6+ | B37: 2032+ | C37: Python + Ghidra | D37: RE automation | E37: Automate triage or metadata extraction from training binaries | F37: ghidra-python-automation | G37: Engineering | H37: Planned | I37: 300 | J37: Leverages your earlier Python skills

Sheet Beyond 25
A1: PROJECT 25 — BEYOND 25 / YEAR 6+ EXTENSION
A2: CCNA has been moved into Project 25 (target: after Security+ in 2027). This sheet is reserved for deeper post-25 specialisations such as cloud security engineering, malware analysis and reverse engineering.
A4: Timeframe | B4: Track | C4: Focus | D4: Skill | E4: Practical Mission | F4: Portfolio Deliverable | G4: Suggested Tools / Study | H4: Priority | I4: Status | J4: XP
A5: Jan–Mar 2032 | B5: Cloud Security | C5: Azure security engineering | D5: Identity + network + workload security | E5: Perform a security review of an Azure lab: IAM, NSGs, Key Vault, logging, Defender for Cloud | F5: azure-cloud-security-review.md | G5: Microsoft Learn / SC-500 | H5: High | I5: Not Started | J5: 300
A6: Mar–Apr 2032 | B6: Malware Analysis | C6: Fundamentals | D6: Static triage | E6: Build an isolated malware-analysis VM workflow and analyse benign training samples / CTF samples | F6: malware-static-triage.md | G6: REMnux / PEStudio / strings / hashes | H6: High | I6: Not Started | J6: 250
